Workbook

Sheet README
A1: Mapped — Simulation & Fact-Check Trackers
A3: How to use | B3: The companion doc 'Mapped_Simulation_Plan_and_SOP.md' explains the why and how. This workbook is where you record what you find. Fill the YELLOW cells. Each sheet has one italic grey EXAMPLE row — delete it before you start.
A4: Legend — yellow cell | B4: You fill it in.
A5: Legend — EXAMPLE row | B5: Sample values showing the expected format. Delete before real use.
A6: Severity | B6: S1 — Critical (broken / wrong-user data / safety) · S2 — Major (wrong or misleading output) · S3 — Minor (confusing/ugly) · S4 — Trivial (cosmetic).
A7: Match / Pass values | B7: Y = matches reference / passes · N = mismatch (log an issue) · — = not applicable / not yet checked.
A9: Sheet index
A10: Personas | B10: The 12 synthetic users, birth data, targets, account, fact-check status.
A11: Coverage | B11: Every surface × persona — tick when exercised; each surface needs ≥3 personas.
A12: Issue Log | B12: Every defect and every 'doesn't make sense' finding, logged live.
A13: FactCheck-Astrology | B13: Big-3, placements, houses vs an independent ephemeris (Astro.com, tropical + Placidus).
A14: FactCheck-Numerology | B14: Life Path / Expression / Soul Urge / Personality / Birthday / Maturity vs hand-calc.
A15: FactCheck-HumanDesign | B15: Type / Authority / Profile / Definition / centers / channels / design-side gates vs MyBodyGraph.
A16: FactCheck-Resonance | B16: Archetype / Animal / Deity / Character — determinism, cost, provenance, face-validity.
A17: Determinism-Cost | B17: Does each generated surface regenerate or spend credits on repeat views?
A18: Weekly-Run-Log | B18: One row per simulated week / session per persona.
A19: Deploy-Regression | B19: Re-checks after each fix/deploy.
A21: Issue dashboard (auto)
A22: Total issues logged | B22: =COUNTA('Issue Log'!A3:A1000) -> 5
A23: S1 — Critical | B23: =COUNTIF('Issue Log'!G3:G1000,"S1 — Critical") -> 0
A24: S2 — Major | B24: =COUNTIF('Issue Log'!G3:G1000,"S2 — Major") -> 3
A25: S3 — Minor | B25: =COUNTIF('Issue Log'!G3:G1000,"S3 — Minor") -> 2
A26: S4 — Trivial | B26: =COUNTIF('Issue Log'!G3:G1000,"S4 — Trivial") -> 0
A27: Still Open | B27: =COUNTIF('Issue Log'!M3:M1000,"Open") -> 0
A28: Personas fact-checked | B28: =COUNTIF(Personas!I2:I13,"Signed off") -> 0

Sheet Personas
A1: ID | B1: Persona | C1: Birth date | D1: Birth time | E1: Birthplace | F1: Timezone note | G1: Edge cases / target to confirm | H1: Account (login) | I1: Fact-check status
A2: P01 | B2: Ava Chen | C2: 1990-07-15 | D2: 14:30 | E2: New York, USA | F2: US Eastern, DST on | G2: Baseline / control; standard 2-word Latin name; Cancer Sun.
A3: P02 | B3: Mateo Rossi | C3: 1985-10-27 | D3: 02:30 | E3: Rome, Italy | F3: CET, DST fall-back weekend | G3: Local time that occurs twice — UTC-offset resolution.
A4: P03 | B4: Zainab Al-Farsi | C4: 1993-02-18 | D4: 23:50 | E4: Dubai, UAE | F4: GST +4, no DST | G4: Near-midnight (date-rollover); name with particle/hyphen.
A5: P04 | B5: Freya Þórsdóttir | C5: 1998-12-21 | D5: 03:10 | E5: Reykjavík, Iceland | F5: GMT+0 | G5: High latitude (Placidus distortion, intercepted signs); non-ASCII name → numerology transliteration.
A6: P05 | B6: Kwame Mensah | C6: 1979-12-31 | D6: 23:55 | E6: Accra, Ghana | F6: GMT+0 | G6: Year-boundary birth; equatorial; pre-1980 historical TZ.
A7: P06 | B7: Mia Nakamura | C7: 2000-02-29 | D7: 12:00 | E7: Tokyo, Japan | F7: JST +9, no DST | G7: Leap day (Feb 29); exact noon.
A8: P07 | B8: Lucas Silva | C8: 1988-02-05 | D8: 21:40 | E8: São Paulo, Brazil | F8: BRT, historical summer-time | G8: Southern hemisphere; Brazil DST whose rules changed.
A9: P08 | B9: Priya Nair | C9: 1995-09-05 | D9: 18:20 | E9: Mumbai, India | F9: IST +5:30 | G9: Half-hour (non-integer) timezone offset.
A10: P09 | B10: Sam Rivers | C10: 1992-04-04 | D10: UNKNOWN | E10: Denver, USA | F10: US Mountain | G10: Unknown birth time → no Rising, no Human Design; tests degraded 'no-birth-time' path everywhere.
A11: P10 | B11: Noor Haddad | C11: 1990-06-13 | D11: 08:15 | E11: Beirut, Lebanon | F11: EET +2 | G11: Master number target (digit-sum 29 → Life Path 11); inspect for karmic-debt numbers.
A12: P11 | B12: Elena Petrova | C12: 1970-06-13 | D12: 10:05 | E12: Moscow, USSR | F12: MSK, Soviet 'decree time' | G12: Target Reflector HD type (~1%; confirm, don't force); Soviet-era TZ oddity.
A13: P12 | B13: Diego Torres-Vega | C13: 1996-04-19 | D13: 05:50 | E13: Mexico City, Mexico | F13: CST | G13: Sun on Aries/Taurus cusp + dawn birth (rising-cusp warning); hyphenated surname for numerology.

Sheet Coverage
A1: Surface / feature | B1: P01 | C1: P02 | D1: P03 | E1: P04 | F1: P05 | G1: P06 | H1: P07 | I1: P08 | J1: P09 | K1: P10 | L1: P11 | M1: P12 | N1: # covered | O1: ≥3?
A2: Chart / Astrology | N2: =COUNTIF(B2:M2,"x") -> 0 | O2: =IF(N2>=3,"OK","under") -> under
A3: Transits | N3: =COUNTIF(B3:M3,"x") -> 0 | O3: =IF(N3>=3,"OK","under") -> under
A4: Synastry / Connections | N4: =COUNTIF(B4:M4,"x") -> 0 | O4: =IF(N4>=3,"OK","under") -> under
A5: Composite | N5: =COUNTIF(B5:M5,"x") -> 0 | O5: =IF(N5>=3,"OK","under") -> under
A6: Solar Return | N6: =COUNTIF(B6:M6,"x") -> 0 | O6: =IF(N6>=3,"OK","under") -> under
A7: Astrocartography | N7: =COUNTIF(B7:M7,"x") -> 0 | O7: =IF(N7>=3,"OK","under") -> under
A8: Numerology | N8: =COUNTIF(B8:M8,"x") -> 0 | O8: =IF(N8>=3,"OK","under") -> under
A9: Human Design | N9: =COUNTIF(B9:M9,"x") -> 0 | O9: =IF(N9>=3,"OK","under") -> under
A10: Palmistry + share card | N10: =COUNTIF(B10:M10,"x") -> 0 | O10: =IF(N10>=3,"OK","under") -> under
A11: Tarot | N11: =COUNTIF(B11:M11,"x") -> 0 | O11: =IF(N11>=3,"OK","under") -> under
A12: Oracle decks | N12: =COUNTIF(B12:M12,"x") -> 0 | O12: =IF(N12>=3,"OK","under") -> under
A13: Dolly (web) | N13: =COUNTIF(B13:M13,"x") -> 0 | O13: =IF(N13>=3,"OK","under") -> under
... A27: Payments (if live) | N27: =COUNTIF(B27:M27,"x") -> 0 | O27: =IF(N27>=3,"OK","under") -> under
A29: Tick 'x' when a persona exercises a surface (both web & mobile where relevant). Target: every surface ≥3 personas.

Sheet Issue Log
A1: ID | B1: Date | C1: Persona | D1: Platform | E1: Surface / Feature | F1: Type | G1: Severity | H1: Title | I1: Steps to reproduce | J1: Expected | K1: Actual | L1: Status | M1: Owner | N1: Fix commit / PR | O1: Evidence link | P1: Notes
A2: I-001 | B2: 2026-01-15 | C2: P06 | D2: web | E2: Chart / Astrology | F2: Calc/Data error | G2: S2 — Major | H2: Feb-29 birth shows wrong Sun degree | I2: Enter P06 birth data; open chart | J2: Sun ~10° Pisces (per Astro.com) | K2: Sun shows 9° Aquarius | L2: Open | O2: link to screenshot | P2: Leap-day handling suspected
A3: I-001 | B3: 2026-08-17 | C3: ALL | D3: web+mobile | E3: Profile / Resonance | F3: Calc/Data error | G3: S2 — Major | H3: Zodiac signs never reach the Resonance engine (abbrev vs full names) | I3: Load any profile; inspect resonance evidence lines | J3: Sun/Moon/Rising + planet signs contribute to archetype/animal/deity/character | K3: Charts store 'Gem'/'Sco'; engine tables keyed 'Gemini'/'Scorpio' → all sign features silently dropped. 12/12 personas' results change when fixed; causes visible concentration (Cowardly Lion 5/12). | L3: Verified | M3: Claude | N3: 89ac556 | O3: scripts/sim/report.json | P3: Root cause of concentration; fix = normalize abbrev→full at engine boundary + ENGINE_VERSION bump | FIXED + regression test (tests/simulationRegressions.test.ts); harness re-run confirms.
A4: I-002 | B4: 2026-08-17 | C4: P09 | D4: web+mobile | E4: Chart / Astrology | F4: Calc/Data error | G4: S2 — Major | H4: Unknown birth time still fabricates Rising sign + house placements | I4: Create chart with unknown time; call calculateChart / read stored planets[].house | J4: rising=null, houses=[] / null when unknownTime | K4: calculateChart returns Rising (Cancer), a rising-cusp warning, and real house numbers from an assumed noon. you/page.tsx guards it, but 20 other consumers (dollyDepth, Interpretations, exportChart, WebToday, chartRuler…) don't → Dolly can assert a false Rising/houses. | L4: Verified | M4: Claude | N4: 89ac556 | O4: scripts/sim/report.json P09 | P4: Fix at source in calculateChart (return null/[] when unknownTime) protects all consumers | FIXED + regression test (tests/simulationRegressions.test.ts); harness re-run confirms.
A5: I-003 | B5: 2026-08-17 | C5: P04 | D5: web+mobile | E5: Numerology | F5: Calc/Data error | G5: S2 — Major | H5: Non-ASCII letters silently stripped from names → wrong Expression/Soul Urge/Personality | I5: Enter name 'Freya Þórsdóttir' (or José García, Zoë Müller) | J5: Letters transliterated (Þ→Th, ó→o) then valued | K5: parseName does .replace(/[^A-Z]/g,'') → deletes Þ,ó,é,ü,ø… Freya: app Ex1/SU6/Pe4 vs correct Ex5/SU9/Pe5; José García: app Ex11/SU8 vs correct Ex7/SU22 (fake master). | L5: Verified | M5: Claude | N5: 89ac556 | P5: Add Unicode NFD-strip + explicit map (Þ→TH, ß→SS, Æ→AE, Ø→O…) before A-Z filter | FIXED + regression test (tests/simulationRegressions.test.ts); harness re-run confirms.
A6: I-004 | B6: 2026-08-17 | C6: P02 | D6: — | E6: Chart / Astrology | F6: Calc/Data error | G6: S3 — Minor | H6: UTC offset sampled at noon UTC, ignores birth hour (DST-transition-day edge) | I6: Birth on a DST switch day, before the switch | J6: Offset for the actual birth instant | K6: getUtcOffsetHours uses a fixed 12:00Z reference → wrong side of a same-day switch (~1h → Ascendant off ~15°). NOTE: my P02 premise was wrong (Italy DST ended 29 Sep in 1985), so app was correct for P02; edge remains real but narrow. | L6: Verified | M6: Claude | N6: c38ae83 | P6: Sample offset at the actual local birth datetime; verify with a real switch-day birth | FIXED. I-004 verified on US+EU switch days both directions, 12 personas unchanged, regression test added. I-005: profile shows "calculated from <name>" + link to edit.
A7: I-005 | B7: 2026-08-17 | C7: ALL | D7: — | E7: Numerology | F7: UX/Confusion | G7: S3 — Minor | H7: Numerology name source not surfaced to user | I7: Open numerology; look for the name used | J7: App shows/lets you confirm the exact full name feeding the calc | K7: Name comes from a stored/display string; user can't see or correct it (spec §6.4 #2 / numerology.source_name). | L7: Verified | M7: Claude | N7: c38ae83 | P7: Show 'calculated from: <name>' + edit affordance | FIXED. I-004 verified on US+EU switch days both directions, 12 personas unchanged, regression test added. I-005: profile shows "calculated from <name>" + link to edit.

Sheet FactCheck-Astrology
A1: Persona | B1: Item | C1: App value | D1: Reference value | E1: Reference (source + settings) | F1: Match (Y/N/—) | G1: Sev if mismatch | H1: Issue ID | I1: Notes
A2: EXAMPLE | B2: Sun — sign | C2: Cancer | D2: Cancer | E2: Astro.com, tropical + Placidus | F2: Y | I2: match
A3: P01 — Ava Chen
B4: Sun — sign | C4: Can | F4: Y | I4: indep ephemeris: sign+deg match
B5: Moon — sign | C5: Ari
B6: Rising / Ascendant — sign | C6: Sco
B7: Mercury — sign & house | C7: Leo 7.28° / H9
B8: Venus — sign & house | C8: Gem 24.74° / H8
B9: Mars — sign & house | C9: Tau 2.12° / H6
B10: Jupiter — sign & house | C10: Can 22.61° / H9
B11: Saturn — sign & house | C11: Cap 21.94° / H3
B12: Uranus — sign & house | C12: Cap 6.96° / H2
B13: Neptune — sign & house | C13: Cap 12.91° / H3
B14: Pluto — sign & house | C14: Sco 15° / H1
B15: North Node — sign & house | C15: Aqu 8.09° / H3
B16: Chiron — sign & house | C16: Can 15.79° / H9
... B18: Edge-case behaviour (this persona's target) | C18: none
A19: P02 — Mateo Rossi
B20: Sun — sign | C20: Sco | F20: Y | I20: indep ephemeris: sign+deg match
B21: Moon — sign | C21: Ari
B22: Rising / Ascendant — sign | C22: Vir
B23: Mercury — sign & house | C23: Sco 23.88° / H3
B24: Venus — sign & house | C24: Lib 13.06° / H2
B25: Mars — sign & house | C25: Vir 29.64° / H1
B26: Jupiter — sign & house | C26: Aqu 8.04° / H5
B27: Saturn — sign & house | C27: Sco 27.56° / H3
B28: Uranus — sign & house | C28: Sag 15.67° / H4
B29: Neptune — sign & house | C29: Cap 1.38° / H4
B30: Pluto — sign & house | C30: Sco 4.64° / H2
B31: North Node — sign & house | C31: Tau 9.32° / H9
B32: Chiron — sign & house | C32: Gem 11.58° / H9
... B34: Edge-case behaviour (this persona's target) | C34: none
A35: P03 — Zainab Al-Farsi
B36: Sun — sign | C36: Pis | F36: Y | I36: indep ephemeris: sign+deg match
B37: Moon — sign | C37: Aqu
B38: Rising / Ascendant — sign | C38: Sco
B39: Mercury — sign & house | C39: Pis 17.93° / H4
B40: Venus — sign & house | C40: Ari 12.71° / H5
B41: Mars — sign & house | C41: Can 8.75° / H8
B42: Jupiter — sign & house | C42: Lib 14.01° / H11
...

Sheet FactCheck-Numerology
A1: Persona | B1: Item | C1: App value | D1: Hand-calc value | E1: Match (Y/N/—) | F1: Sev if mismatch | G1: Issue ID | H1: Notes
A2: EXAMPLE | B2: Life Path | C2: 11 | D2: 11 | E2: Y | H2: master preserved
A3: P01 — Ava Chen
B4: Life Path | C4: 5 | D4: 5 | E4: Y
B5: Expression | C5: 9
B6: Soul Urge | C6: 7
B7: Personality | C7: 11
B8: Birthday | C8: 6 | D8: 6 | E8: Y
B9: Maturity | C9: 5
B10: Master numbers present (11/22/33) | C10: [11]
B11: Karmic-debt numbers (13/14/16/19) | C11: [14]
B12: Name string used (exact) | C12: Ava Chen
B13: Reduction method confirmed | C13: Pythagorean, masters kept, Y/M/D reduced separately (verified)
A14: P02 — Mateo Rossi
B15: Life Path | C15: 6 | D15: 6 | E15: Y
B16: Expression | C16: 8
B17: Soul Urge | C17: 9
B18: Personality | C18: 8
B19: Birthday | C19: 9 | D19: 9 | E19: Y
B20: Maturity | C20: 5
B21: Master numbers present (11/22/33) | C21: []
B22: Karmic-debt numbers (13/14/16/19) | C22: [14]
B23: Name string used (exact) | C23: Mateo Rossi
B24: Reduction method confirmed | C24: Pythagorean, masters kept, Y/M/D reduced separately (verified)
A25: P03 — Zainab Al-Farsi
B26: Life Path | C26: 33 | D26: 33 | E26: Y
B27: Expression | C27: 11
B28: Soul Urge | C28: 22
B29: Personality | C29: 7
B30: Birthday | C30: 9 | D30: 9 | E30: Y
B31: Maturity | C31: 8
B32: Master numbers present (11/22/33) | C32: [33, 11, 22]
B33: Karmic-debt numbers (13/14/16/19) | C33: []
B34: Name string used (exact) | C34: Zainab Al-Farsi
B35: Reduction method confirmed | C35: Pythagorean, masters kept, Y/M/D reduced separately (verified)
A36: P04 — Freya Þórsdóttir
B37: Life Path | C37: 6 | D37: 6 | E37: Y
B38: Expression | C38: 1 | E38: N | H38: BUG: non-ASCII letters (Þ,ó) silently stripped → wrong numbers
B39: Soul Urge | C39: 6 | E39: N | H39: BUG: non-ASCII letters (Þ,ó) silently stripped → wrong numbers
B40: Personality | C40: 4 | E40: N | H40: BUG: non-ASCII letters (Þ,ó) silently stripped → wrong numbers
...

Sheet FactCheck-HumanDesign
A1: Persona | B1: Item | C1: App value | D1: Reference (MyBodyGraph) | E1: Match (Y/N/—) | F1: Sev if mismatch | G1: Issue ID | H1: Notes
A2: EXAMPLE | B2: Type | C2: Projector | D2: Projector | E2: Y | H2: design-side confirmed
A3: P01 — Ava Chen
B4: Type | C4: Reflector
B5: Strategy
B6: Authority | C6: Lunar (Reflector)
B7: Profile (both lines) | C7: 3/5
B8: Definition | C8: No Definition
B9: Defined centers (list) | C9: (none — Reflector)
B10: Channels (list) | C10: (none)
B11: Personality gates (spot-check ≥3)
B12: Design-side gates (spot-check ≥3)
B13: Incarnation cross | C13: Right Angle Cross (62/61 | 42/32)
A14: P02 — Mateo Rossi
B15: Type | C15: Generator
B16: Strategy
B17: Authority | C17: Sacral
B18: Profile (both lines) | C18: 2/4
B19: Definition | C19: Single Definition
B20: Defined centers (list) | C20: g, sacral
B21: Channels (list) | C21: 2-14, 29-46
B22: Personality gates (spot-check ≥3)
B23: Design-side gates (spot-check ≥3)
B24: Incarnation cross | C24: Right Angle Cross (28/27 | 31/41)
A25: P03 — Zainab Al-Farsi
B26: Type | C26: Manifesting Generator
B27: Strategy
B28: Authority | C28: Emotional
B29: Profile (both lines) | C29: 1/3
B30: Definition | C30: Split Definition
B31: Defined centers (list) | C31: throat, heart, sacral, solarPlexus, root
B32: Channels (list) | C32: 19-49, 20-34, 21-45
B33: Personality gates (spot-check ≥3)
B34: Design-side gates (spot-check ≥3)
B35: Incarnation cross | C35: Right Angle Cross (55/59 | 34/20)
A36: P04 — Freya Þórsdóttir
B37: Type | C37: Generator
B38: Strategy
B39: Authority | C39: Sacral
B40: Profile (both lines) | C40: 1/3
...

Sheet FactCheck-Resonance
A1: Persona | B1: Check | C1: Value / result | D1: Pass (Y/N/—) | E1: Notes
A2: EXAMPLE | B2: Archetype — primary | C2: The Gate | D2: Y | E2: coherent w/ Scorpio 8th
A3: P01 — Ava Chen
B4: Archetype — primary | C4: The Undertow | D4: Y | E4: signs now reach engine (I-001 fixed)
B5: Archetype — secondary / 'shaded by' | C5: The Crossroads
B6: Animal guide (+ tier) | C6: Lizard [widely-shared]
B7: Animal provenance correct? (source + 'Animal Guide' term, within cultural gate)
B8: Deity (+ tier) | C8: Loki [open]
B9: Deity phrasing correct? (living-open = comparative, within cultural gate)
B10: Character (+ work) | C10: Mowgli
B11: Deterministic on reload (identical every time)? | C11: identical ×2 runs | D11: Y
B12: No AI-credit spend on reload?
B13: Face-validity — plausible for this chart? (why)
B14: Evidence lines cite this persona's real placements? | C14: Reflector, Cancer Sun, Life Path 5, Scorpio Rising | D14: Y | E14: Sun/Moon/Rising present
A15: P02 — Mateo Rossi
B16: Archetype — primary | C16: The Crypt | D16: Y | E16: signs now reach engine (I-001 fixed)
B17: Archetype — secondary / 'shaded by' | C17: The Bedrock
B18: Animal guide (+ tier) | C18: Crocodile [attested]
B19: Animal provenance correct? (source + 'Animal Guide' term, within cultural gate)
B20: Deity (+ tier) | C20: Tlaloc [open]
B21: Deity phrasing correct? (living-open = comparative, within cultural gate)
B22: Character (+ work) | C22: Frankenstein's Creature
B23: Deterministic on reload (identical every time)? | C23: identical ×2 runs | D23: Y
B24: No AI-credit spend on reload?
B25: Face-validity — plausible for this chart? (why)
B26: Evidence lines cite this persona's real placements? | C26: Scorpio Sun, Life Path 6, Generator, Virgo Rising | D26: Y | E26: Sun/Moon/Rising present
A27: P03 — Zainab Al-Farsi
B28: Archetype — primary | C28: The Spiral | D28: Y | E28: signs now reach engine (I-001 fixed)
B29: Archetype — secondary / 'shaded by' | C29: The Lens
B30: Animal guide (+ tier) | C30: Nightingale [attested]
B31: Animal provenance correct? (source + 'Animal Guide' term, within cultural gate)
B32: Deity (+ tier) | C32: Ganga [living-open]
B33: Deity phrasing correct? (living-open = comparative, within cultural gate)
B34: Character (+ work) | C34: Sydney Carton
B35: Deterministic on reload (identical every time)? | C35: identical ×2 runs | D35: Y
B36: No AI-credit spend on reload?
B37: Face-validity — plausible for this chart? (why)
B38: Evidence lines cite this persona's real placements? | C38: Pisces Sun, Manifesting Generator, Life Path 33, Scorpio Rising | D38: Y | E38: Sun/Moon/Rising present
A39: P04 — Freya Þórsdóttir
B40: Archetype — primary | C40: The Waystone | D40: Y | E40: signs now reach engine (I-001 fixed)
...

Sheet Determinism-Cost
A1: Surface | B1: Expected | C1: Regenerates on reload? (Y/N) | D1: Credits before | E1: Credits after | F1: Delta | G1: Pass | H1: Notes
A2: Chart interpretation text | B2: Fixed | F2: =IF(OR(D2="",E2=""),"",E2-D2) | G2: =IF(OR(C2="",D2="",E2=""),"",IF(B2="Fixed",IF(AND(F2=0,C2="No"),"PASS","FAIL"),"n/a"))
A3: Numerology text | B3: Fixed | F3: =IF(OR(D3="",E3=""),"",E3-D3) | G3: =IF(OR(C3="",D3="",E3=""),"",IF(B3="Fixed",IF(AND(F3=0,C3="No"),"PASS","FAIL"),"n/a"))
A4: Human Design text | B4: Fixed | F4: =IF(OR(D4="",E4=""),"",E4-D4) | G4: =IF(OR(C4="",D4="",E4=""),"",IF(B4="Fixed",IF(AND(F4=0,C4="No"),"PASS","FAIL"),"n/a"))
A5: Placement detail (e.g. 'Mars in 8th') | B5: Fixed | F5: =IF(OR(D5="",E5=""),"",E5-D5) | G5: =IF(OR(C5="",D5="",E5=""),"",IF(B5="Fixed",IF(AND(F5=0,C5="No"),"PASS","FAIL"),"n/a"))
A6: Archetype | B6: Fixed | F6: =IF(OR(D6="",E6=""),"",E6-D6) | G6: =IF(OR(C6="",D6="",E6=""),"",IF(B6="Fixed",IF(AND(F6=0,C6="No"),"PASS","FAIL"),"n/a"))
A7: Animal guide | B7: Fixed | F7: =IF(OR(D7="",E7=""),"",E7-D7) | G7: =IF(OR(C7="",D7="",E7=""),"",IF(B7="Fixed",IF(AND(F7=0,C7="No"),"PASS","FAIL"),"n/a"))
A8: Deity | B8: Fixed | F8: =IF(OR(D8="",E8=""),"",E8-D8) | G8: =IF(OR(C8="",D8="",E8=""),"",IF(B8="Fixed",IF(AND(F8=0,C8="No"),"PASS","FAIL"),"n/a"))
A9: Character | B9: Fixed | F9: =IF(OR(D9="",E9=""),"",E9-D9) | G9: =IF(OR(C9="",D9="",E9=""),"",IF(B9="Fixed",IF(AND(F9=0,C9="No"),"PASS","FAIL"),"n/a"))
A10: Tarot / Oracle reading (a saved pull) | B10: Fixed | F10: =IF(OR(D10="",E10=""),"",E10-D10) | G10: =IF(OR(C10="",D10="",E10=""),"",IF(B10="Fixed",IF(AND(F10=0,C10="No"),"PASS","FAIL"),"n/a"))
A11: Dolly reply | B11: Time-sensitive | F11: =IF(OR(D11="",E11=""),"",E11-D11) | G11: =IF(OR(C11="",D11="",E11=""),"",IF(B11="Fixed",IF(AND(F11=0,C11="No"),"PASS","FAIL"),"n/a"))
A12: Today's transits | B12: Time-sensitive | F12: =IF(OR(D12="",E12=""),"",E12-D12) | G12: =IF(OR(C12="",D12="",E12=""),"",IF(B12="Fixed",IF(AND(F12=0,C12="No"),"PASS","FAIL"),"n/a"))
A13: Near-future transits | B13: Time-sensitive | F13: =IF(OR(D13="",E13=""),"",E13-D13) | G13: =IF(OR(C13="",D13="",E13=""),"",IF(B13="Fixed",IF(AND(F13=0,C13="No"),"PASS","FAIL"),"n/a"))
A15: Fixed surfaces must NOT regenerate and must NOT spend credits on repeat views (delta = 0, regenerates = No). Time-sensitive surfaces may recompute — that's expected and typically free/calculated.

Sheet Weekly-Run-Log
A1: Session ID | B1: Date | C1: Persona | D1: Sim-week (1–12) | E1: Platform | F1: Surfaces touched | G1: Issues opened (IDs) | H1: Notes
A2: S-001 | B2: 2026-01-15 | C2: P01 | D2: 1 | E2: web | F2: Home, Journal (morning), Tarot→Dolly, Transits | G2: I-001, I-002 | H2: first pass

Sheet Deploy-Regression
A1: Build / commit | B1: Date | C1: Issue ID re-tested | D1: Persona | E1: Result | F1: resonance:validate | G1: Smoke re-check | H1: Notes
A2: 6b048f6 | B2: 2026-01-16 | C2: I-001 | D2: P06 | E2: Pass | F2: PASS (gates green) | G2: 1 astro line re-checked OK | H2: leap-day fix verified
A3: 89ac556 | B3: 2026-08-17 | C3: I-001, I-002, I-003 | D3: ALL / P09 / P04 | E3: Pass | F3: PASS (3/3 gates) | G3: 70/70 tests; harness: 0/12 personas change abbrev vs full; P09 rising/houses null; José García Ex7/SU22 | H3: All three S2 fixes verified via scripts/sim/run.mts re-run
A4: c38ae83 | B4: 2026-08-17 | C4: I-004, I-005 | D4: switch-day cases / ALL | E4: Pass | F4: PASS (3/3) | G4: 71/71 tests; 12 personas byte-identical after I-004; profile name line renders | H4: DST offset now resolved at birth instant; numerology name surfaced
